Workbook

Sheet Read Me
A1: Statement of Applicability: Saarland University
A2: PORTFOLIO EXERCISE. Not an official document of Saarland University.
A4: Purpose
A5: Statement of Applicability (SoA) as required by ISO/IEC 27001:2022 clause 6.1.3 d). It lists all 93 controls of Annex A, says whether each is applicable, why it is included or excluded, and how far it is implemented.
A6: Control titles are short paraphrases, not the wording of the standard. The full text is in ISO/IEC 27001:2022 and the guidance in ISO/IEC 27002:2022 (paid, not included).
A7: All statuses, owners, justifications and documents are invented for illustration and do not describe the university's real security posture.
A9: Scope (assumed)
A10: Information and IT services of the central university administration and of the University IT Centre (HIZ) at the Saarbrücken and Homburg campuses, including services offered to faculties and institutes. Systems run by institutes themselves are in scope where they connect to the campus network.
A12: Sheets
A13: SoA: one row per Annex A control with applicability, reasons for inclusion, justification, implementation status, owner, evidence and the risks it treats.
A14: Related risks are read from the risk register (column L of its Risk Register sheet) when the workbook is built: 39 controls treat at least one of its risks.
A15: Summary: counts by theme and status, calculated with formulas.
... A28: Version 0.1, prepared 08 October 2026.

Sheet SoA
A1: Statement of Applicability: ISO/IEC 27001:2022 Annex A
A2: Portfolio exercise for Saarland University. Paraphrased control titles; all statuses and details are invented. Not an official university document.
A4: Control | B4: Control (paraphrased title) | C4: Theme | D4: Applicable | E4: R: Risk treatment | F4: L: Legal / regulatory | G4: C: Contractual | H4: B: Baseline | I4: Justification for inclusion or exclusion | J4: Implementation status | K4: Control owner (role) | L4: Evidence / reference document | M4: Related risks (from register) | N4: Number of related risks
A5: A.5.1 | B5: Security policy set and reviewed | C5: Organisational | D5: Yes | F5: X | H5: X | I5: Top-level policy is the basis of the ISMS; required to show management direction. | J5: Implemented | K5: University Executive Board | L5: Information Security Policy | N5: =IF(M5="",0,LEN(M5)-LEN(SUBSTITUTE(M5,",",""))+1)
A6: A.5.2 | B6: Security roles and duties | C6: Organisational | D6: Yes | E6: X | H6: X | I6: Responsibilities are split between HIZ, faculties and institutes; roles must be written down. | J6: Partially implemented | K6: University Executive Board | L6: ISMS Roles Charter | M6: R17 | N6: =IF(M6="",0,LEN(M6)-LEN(SUBSTITUTE(M6,",",""))+1)
A7: A.5.3 | B7: Separating conflicting duties | C7: Organisational | D7: Yes | H7: X | I7: Small admin teams often request and approve their own changes. | J7: Partially implemented | K7: Head of University IT Centre (HIZ) | L7: Access Control Guideline | N7: =IF(M7="",0,LEN(M7)-LEN(SUBSTITUTE(M7,",",""))+1)
A8: A.5.4 | B8: Management duties for security | C8: Organisational | D8: Yes | H8: X | I8: Deans and heads of department must enforce the policy in their units. | J8: Implemented | K8: University Executive Board | L8: Information Security Policy | N8: =IF(M8="",0,LEN(M8)-LEN(SUBSTITUTE(M8,",",""))+1)
A9: A.5.5 | B9: Contact with public authorities | C9: Organisational | D9: Yes | F9: X | I9: Breach reports to the data protection supervisor and contact with police and BSI after attacks. | J9: Implemented | K9: Chief Information Security Officer (CISO) | L9: Incident Response Plan | N9: =IF(M9="",0,LEN(M9)-LEN(SUBSTITUTE(M9,",",""))+1)
A10: A.5.6 | B10: Contact with specialist groups | C10: Organisational | D10: Yes | H10: X | I10: Exchange with the university CERT community and research network security teams. | J10: Implemented | K10: Chief Information Security Officer (CISO) | L10: ISMS Roles Charter | N10: =IF(M10="",0,LEN(M10)-LEN(SUBSTITUTE(M10,",",""))+1)
A11: A.5.7 | B11: Threat intelligence gathering | C11: Organisational | D11: Yes | E11: X | I11: Universities are targets for ransomware and research espionage; warnings are not collected systematically. | J11: Not implemented | K11: Chief Information Security Officer (CISO) | L11: Planned: Threat Intelligence Procedure | M11: R11 | N11: =IF(M11="",0,LEN(M11)-LEN(SUBSTITUTE(M11,",",""))+1)
A12: A.5.8 | B12: Security in project management | C12: Organisational | D12: Yes | H12: X | I12: IT and research projects start without a security check today. | J12: Partially implemented | K12: Chief Information Security Officer (CISO) | L12: Project Management Guideline | N12: =IF(M12="",0,LEN(M12)-LEN(SUBSTITUTE(M12,",",""))+1)
A13: A.5.9 | B13: Asset inventory | C13: Organisational | D13: Yes | E13: X | I13: Central systems are listed; institute servers are not. | J13: Partially implemented | K13: Head of University IT Centre (HIZ) | L13: Configuration Management Database | M13: R06 | N13: =IF(M13="",0,LEN(M13)-LEN(SUBSTITUTE(M13,",",""))+1)
A14: A.5.10 | B14: Rules for acceptable use of assets | C14: Organisational | D14: Yes | E14: X | H14: X | I14: IT usage regulations exist but do not cover public AI tools. | J14: Partially implemented | K14: Chief Information Security Officer (CISO) | L14: IT Usage Regulations | M14: R18 | N14: =IF(M14="",0,LEN(M14)-LEN(SUBSTITUTE(M14,",",""))+1)
A15: A.5.11 | B15: Returning assets on leaving | C15: Organisational | D15: Yes | H15: X | I15: Keys and laptops are returned on request only; guest researchers are often missed. | J15: Partially implemented | K15: Director of Human Resources | L15: HR Security Procedure | N15: =IF(M15="",0,LEN(M15)-LEN(SUBSTITUTE(M15,",",""))+1)
A16: A.5.12 | B16: Information classification | C16: Organisational | D16: Yes | E16: X | F16: X | I16: Research, health and exam data need different protection; no scheme exists yet. | J16: Planned | K16: Vice President for Research | L16: Planned: Classification Guideline | M16: R03, R11 | N16: =IF(M16="",0,LEN(M16)-LEN(SUBSTITUTE(M16,",",""))+1)
A17: A.5.13 | B17: Labelling information | C17: Organisational | D17: Yes | H17: X | I17: Follows the classification scheme so staff can see how to handle a document. | J17: Planned | K17: Vice President for Research | L17: Planned: Classification Guideline | N17: =IF(M17="",0,LEN(M17)-LEN(SUBSTITUTE(M17,",",""))+1)
A18: A.5.14 | B18: Transferring information | C18: Organisational | D18: Yes | E18: X | F18: X | I18: Personal data is shared by email, cloud links and with external partners. | J18: Partially implemented | K18: Data Protection Officer | L18: Data Transfer Guideline | M18: R10, R18 | N18: =IF(M18="",0,LEN(M18)-LEN(SUBSTITUTE(M18,",",""))+1)
A19: A.5.15 | B19: Access control rules | C19: Organisational | D19: Yes | E19: X | F19: X | I19: Need-to-know rules exist for central systems, not for shared drives. | J19: Partially implemented | K19: Head of University IT Centre (HIZ) | L19: Access Control Guideline | M19: R10 | N19: =IF(M19="",0,LEN(M19)-LEN(SUBSTITUTE(M19,",",""))+1)
A20: A.5.16 | B20: Managing identities | C20: Organisational | D20: Yes | E20: X | I20: One identity per person across staff, students and guests is the base of all access. | J20: Partially implemented | K20: Head of University IT Centre (HIZ) | L20: Identity Management Concept | M20: R09 | N20: =IF(M20="",0,LEN(M20)-LEN(SUBSTITUTE(M20,",",""))+1)
A21: A.5.17 | B21: Handling authentication secrets | C21: Organisational | D21: Yes | E21: X | H21: X | I21: Password rules and secure reset via the service desk are in place. | J21: Implemented | K21: Head of University IT Centre (HIZ) | L21: Password Guideline | M21: R02 | N21: =IF(M21="",0,LEN(M21)-LEN(SUBSTITUTE(M21,",",""))+1)
A22: A.5.18 | B22: Granting and reviewing access rights | C22: Organisational | D22: Yes | E22: X | I22: Rights are granted on request but rarely reviewed or removed. | J22: Partially implemented | K22: Head of University IT Centre (HIZ) | L22: Access Control Guideline | M22: R08, R09 | N22: =IF(M22="",0,LEN(M22)-LEN(SUBSTITUTE(M22,",",""))+1)
A23: A.5.19 | B23: Security with suppliers | C23: Organisational | D23: Yes | E23: X | G23: X | I23: Core services (network, cloud, campus management) depend on external suppliers. | J23: Planned | K23: Head of Procurement | L23: Planned: Supplier Security Guideline | M23: R05 | N23: =IF(M23="",0,LEN(M23)-LEN(SUBSTITUTE(M23,",",""))+1)
A24: A.5.20 | B24: Security terms in supplier contracts | C24: Organisational | D24: Yes | F24: X | G24: X | I24: Data processing agreements are signed; security clauses are not standard yet. | J24: Partially implemented | K24: Head of Procurement | L24: Contract templates | N24: =IF(M24="",0,LEN(M24)-LEN(SUBSTITUTE(M24,",",""))+1)
A25: A.5.21 | B25: ICT supply chain security | C25: Organisational | D25: Yes | E25: X | I25: Single network uplink and cloud services create supply chain exposure. | J25: Not implemented | K25: Head of University IT Centre (HIZ) | L25: Planned: Supplier Security Guideline | M25: R05 | N25: =IF(M25="",0,LEN(M25)-LEN(SUBSTITUTE(M25,",",""))+1)
A26: A.5.22 | B26: Monitoring supplier services and changes | C26: Organisational | D26: Yes | G26: X | I26: Supplier performance and security changes are not reviewed. | J26: Not implemented | K26: Head of Procurement | L26: Planned: Supplier Security Guideline | N26: =IF(M26="",0,LEN(M26)-LEN(SUBSTITUTE(M26,",",""))+1)
A27: A.5.23 | B27: Security for cloud services | C27: Organisational | D27: Yes | F27: X | I27: Collaboration and teaching tools run in the cloud; selection rules exist, exit plans do not. | J27: Partially implemented | K27: Head of University IT Centre (HIZ) | L27: Cloud Usage Guideline | N27: =IF(M27="",0,LEN(M27)-LEN(SUBSTITUTE(M27,",",""))+1)
A28: A.5.24 | B28: Planning for incident management | C28: Organisational | D28: Yes | E28: X | F28: X | I28: A response process exists on paper but has not been exercised. | J28: Partially implemented | K28: Chief Information Security Officer (CISO) | L28: Incident Response Plan | M28: R15 | N28: =IF(M28="",0,LEN(M28)-LEN(SUBSTITUTE(M28,",",""))+1)
A29: A.5.25 | B29: Assessing security events | C29: Organisational | D29: Yes | H29: X | I29: Service desk forwards suspicious events; triage criteria are informal. | J29: Partially implemented | K29: Chief Information Security Officer (CISO) | L29: Incident Response Plan | N29: =IF(M29="",0,LEN(M29)-LEN(SUBSTITUTE(M29,",",""))+1)
A30: A.5.26 | B30: Responding to incidents | C30: Organisational | D30: Yes | E30: X | F30: X | I30: Needed to contain attacks and meet the 72-hour GDPR breach reporting deadline. | J30: Partially implemented | K30: Chief Information Security Officer (CISO) | L30: Incident Response Plan | M30: R15 | N30: =IF(M30="",0,LEN(M30)-LEN(SUBSTITUTE(M30,",",""))+1)
A31: A.5.27 | B31: Learning from incidents | C31: Organisational | D31: Yes | H31: X | I31: No lessons-learned review after incidents so far. | J31: Not implemented | K31: Chief Information Security Officer (CISO) | L31: Incident Response Plan | N31: =IF(M31="",0,LEN(M31)-LEN(SUBSTITUTE(M31,",",""))+1)
A32: A.5.28 | B32: Collecting evidence | C32: Organisational | D32: Yes | F32: X | I32: Evidence may be needed for police, disciplinary or court cases. | J32: Not implemented | K32: Chief Information Security Officer (CISO) | L32: Planned: Forensics Procedure | N32: =IF(M32="",0,LEN(M32)-LEN(SUBSTITUTE(M32,",",""))+1)
A33: A.5.29 | B33: Security during disruption | C33: Organisational | D33: Yes | E33: X | I33: Security must be kept up while systems are restored after a major attack. | J33: Planned | K33: Chief Information Security Officer (CISO) | L33: Business Continuity Plan | M33: R01 | N33: =IF(M33="",0,LEN(M33)-LEN(SUBSTITUTE(M33,",",""))+1)
A34: A.5.30 | B34: ICT readiness for continuity | C34: Organisational | D34: Yes | E34: X | I34: Enrolment, exams and payroll depend on IT being restored in time. | J34: Planned | K34: Head of University IT Centre (HIZ) | L34: Business Continuity Plan | M34: R05, R07 | N34: =IF(M34="",0,LEN(M34)-LEN(SUBSTITUTE(M34,",",""))+1)
A35: A.5.31 | B35: Legal, regulatory and contract requirements | C35: Organisational | D35: Yes | F35: X | G35: X | I35: Data protection law, research funder terms and export rules apply. | J35: Partially implemented | K35: Head of Legal Affairs | L35: Register of legal requirements | N35: =IF(M35="",0,LEN(M35)-LEN(SUBSTITUTE(M35,",",""))+1)
A36: A.5.32 | B36: Intellectual property rights | C36: Organisational | D36: Yes | F36: X | G36: X | I36: Software licences and research results must be protected. | J36: Implemented | K36: Head of Legal Affairs | L36: Licence Management Procedure | N36: =IF(M36="",0,LEN(M36)-LEN(SUBSTITUTE(M36,",",""))+1)
A37: A.5.33 | B37: Protecting records | C37: Organisational | D37: Yes | F37: X | I37: Student, exam and HR records have legal retention periods. | J37: Implemented | K37: Head of Legal Affairs | L37: Records Retention Schedule | N37: =IF(M37="",0,LEN(M37)-LEN(SUBSTITUTE(M37,",",""))+1)
A38: A.5.34 | B38: Privacy and personal data | C38: Organisational | D38: Yes | E38: X | F38: X | I38: Personal data of students, staff, applicants and study participants is processed. | J38: Partially implemented | K38: Data Protection Officer | L38: Records of Processing Activities | M38: R03, R10 | N38: =IF(M38="",0,LEN(M38)-LEN(SUBSTITUTE(M38,",",""))+1)
A39: A.5.35 | B39: Independent security review | C39: Organisational | D39: Yes | H39: X | I39: Internal audit of the ISMS is planned once core controls are in place. | J39: Planned | K39: University Executive Board | L39: Planned: Internal Audit Programme | N39: =IF(M39="",0,LEN(M39)-LEN(SUBSTITUTE(M39,",",""))+1)
A40: A.5.36 | B40: Compliance with security policies and standards | C40: Organisational | D40: Yes | H40: X | I40: Faculties and institutes are not checked against the policy. | J40: Not implemented | K40: Chief Information Security Officer (CISO) | L40: Planned: Internal Audit Programme | N40: =IF(M40="",0,LEN(M40)-LEN(SUBSTITUTE(M40,",",""))+1)
A41: A.5.37 | B41: Documented operating procedures | C41: Organisational | D41: Yes | E41: X | I41: Key systems depend on a few people's knowledge. | J41: Partially implemented | K41: Head of University IT Centre (HIZ) | L41: HIZ operations handbook | M41: R17 | N41: =IF(M41="",0,LEN(M41)-LEN(SUBSTITUTE(M41,",",""))+1)
...

Sheet Summary
A1: SoA Summary
A2: Calculated from the SoA sheet (rows 5 to 97). Portfolio exercise.
A4: KPI | B4: Value
A5: Annex A controls | B5: =COUNTA(SoA!$A$5:$A$97)
A6: Applicable | B6: =COUNTIF(SoA!$D$5:$D$97,"Yes")
A7: Excluded | B7: =COUNTIF(SoA!$D$5:$D$97,"No")
A8: Applicable and fully implemented | B8: =COUNTIFS(SoA!$D$5:$D$97,"Yes",SoA!$J$5:$J$97,"Implemented")
A9: Implementation rate (fully implemented / applicable) | B9: =IFERROR(B8/B6,0)
A10: Applicable controls linked to at least one risk | B10: =COUNTIFS(SoA!$D$5:$D$97,"Yes",SoA!$N$5:$N$97,">0")
A12: Applicable controls by theme and implementation status
A13: Theme | B13: Implemented | C13: Partially implemented | D13: Planned | E13: Not implemented | F13: Applicable | G13: Excluded
A14: Organisational | B14: =COUNTIFS(SoA!$C$5:$C$97,$A14,SoA!$D$5:$D$97,"Yes",SoA!$J$5:$J$97,B$13) | C14: =COUNTIFS(SoA!$C$5:$C$97,$A14,SoA!$D$5:$D$97,"Yes",SoA!$J$5:$J$97,C$13) | D14: =COUNTIFS(SoA!$C$5:$C$97,$A14,SoA!$D$5:$D$97,"Yes",SoA!$J$5:$J$97,D$13) | E14: =COUNTIFS(SoA!$C$5:$C$97,$A14,SoA!$D$5:$D$97,"Yes",SoA!$J$5:$J$97,E$13) | F14: =COUNTIFS(SoA!$C$5:$C$97,$A14,SoA!$D$5:$D$97,"Yes") | G14: =COUNTIFS(SoA!$C$5:$C$97,$A14,SoA!$D$5:$D$97,"No")
A15: People | B15: =COUNTIFS(SoA!$C$5:$C$97,$A15,SoA!$D$5:$D$97,"Yes",SoA!$J$5:$J$97,B$13) | C15: =COUNTIFS(SoA!$C$5:$C$97,$A15,SoA!$D$5:$D$97,"Yes",SoA!$J$5:$J$97,C$13) | D15: =COUNTIFS(SoA!$C$5:$C$97,$A15,SoA!$D$5:$D$97,"Yes",SoA!$J$5:$J$97,D$13) | E15: =COUNTIFS(SoA!$C$5:$C$97,$A15,SoA!$D$5:$D$97,"Yes",SoA!$J$5:$J$97,E$13) | F15: =COUNTIFS(SoA!$C$5:$C$97,$A15,SoA!$D$5:$D$97,"Yes") | G15: =COUNTIFS(SoA!$C$5:$C$97,$A15,SoA!$D$5:$D$97,"No")
A16: Physical | B16: =COUNTIFS(SoA!$C$5:$C$97,$A16,SoA!$D$5:$D$97,"Yes",SoA!$J$5:$J$97,B$13) | C16: =COUNTIFS(SoA!$C$5:$C$97,$A16,SoA!$D$5:$D$97,"Yes",SoA!$J$5:$J$97,C$13) | D16: =COUNTIFS(SoA!$C$5:$C$97,$A16,SoA!$D$5:$D$97,"Yes",SoA!$J$5:$J$97,D$13) | E16: =COUNTIFS(SoA!$C$5:$C$97,$A16,SoA!$D$5:$D$97,"Yes",SoA!$J$5:$J$97,E$13) | F16: =COUNTIFS(SoA!$C$5:$C$97,$A16,SoA!$D$5:$D$97,"Yes") | G16: =COUNTIFS(SoA!$C$5:$C$97,$A16,SoA!$D$5:$D$97,"No")
A17: Technological | B17: =COUNTIFS(SoA!$C$5:$C$97,$A17,SoA!$D$5:$D$97,"Yes",SoA!$J$5:$J$97,B$13) | C17: =COUNTIFS(SoA!$C$5:$C$97,$A17,SoA!$D$5:$D$97,"Yes",SoA!$J$5:$J$97,C$13) | D17: =COUNTIFS(SoA!$C$5:$C$97,$A17,SoA!$D$5:$D$97,"Yes",SoA!$J$5:$J$97,D$13) | E17: =COUNTIFS(SoA!$C$5:$C$97,$A17,SoA!$D$5:$D$97,"Yes",SoA!$J$5:$J$97,E$13) | F17: =COUNTIFS(SoA!$C$5:$C$97,$A17,SoA!$D$5:$D$97,"Yes") | G17: =COUNTIFS(SoA!$C$5:$C$97,$A17,SoA!$D$5:$D$97,"No")
A18: Total | B18: =SUM(B14:B17) | C18: =SUM(C14:C17) | D18: =SUM(D14:D17) | E18: =SUM(E14:E17) | F18: =SUM(F14:F17) | G18: =SUM(G14:G17)
A20: Reasons for inclusion (a control can have several)
A21: Reason | B21: Controls
A22: R: Risk treatment | B22: =COUNTIF(SoA!$E$5:$E$97,"X")
A23: L: Legal / regulatory | B23: =COUNTIF(SoA!$F$5:$F$97,"X")
A24: C: Contractual | B24: =COUNTIF(SoA!$G$5:$G$97,"X")
A25: B: Baseline good practice | B25: =COUNTIF(SoA!$H$5:$H$97,"X")

Sheet Lists
A1: Applicable | B1: Status | C1: Flag
A2: Yes | B2: Implemented | C2: X
A3: No | B3: Partially implemented
B4: Planned
B5: Not implemented
B6: Not applicable

Sheet Sources
A1: Sources
A2: Checked 8 October 2026. Everything not listed here (statuses, owners, documents, scope) is invented for the exercise.
A4: Type | B4: Source | C4: Link | D4: What it supports | E4: Used in | F4: Access
A5: Standard | B5: ISO/IEC 27001:2022 Information security management systems: Requirements (with Amd 1:2024) | C5: https://www.iso.org/standard/27001 | D5: Clause 6.1.3 d) requires a Statement of Applicability; Annex A lists the 93 controls in four themes | E5: Whole SoA; control numbers and themes | F5: Paid standard (about CHF 155), no copy included
A6: Standard | B6: ISO/IEC 27002:2022 Information security controls | C6: https://www.iso.org/standard/75652.html | D6: Purpose and guidance for each control, used to write the paraphrased titles and justifications | E6: Columns B and I | F6: Paid standard, no copy included
A7: Law | B7: EU General Data Protection Regulation (GDPR), Regulation (EU) 2016/679 | C7: https://eur-lex.europa.eu/eli/reg/2016/679/oj | D7: Art. 32 security of processing; Art. 33 breach notification within 72 hours | E7: Reason L; A.5.26, A.5.34, A.8.10, A.8.11 and others | F7: Free
A8: Law | B8: Basic Law for the Federal Republic of Germany (Grundgesetz), Art. 5(3) | C8: https://www.gesetze-im-internet.de/gg/art_5.html | D8: Freedom of science, research and teaching, the reason web filtering is limited to known malicious sites | E8: A.8.23 | F8: Free
A9: Internal | B9: Saarland University risk register (this project) | C9: ../risk-register/saarland-university-risk-register.xlsx | D9: Risks R01 to R18 and the Annex A controls that treat them | E9: Column M (related risks), reason R | F9: Included in this repository
